notice] A new release of pip is available: 25.0.1 -> 25.1.1
[notice] To update, run: pip install --upgrade pip
Installing Node.js for translators library...
  % Total    % Received % Xferd  Average Speed   Time    Time     Time  Current
                                 Dload  Upload   Total   Spent    Left  Speed
100 24.3M  100 24.3M    0     0  10.8M      0  0:00:02  0:00:02 --:--:-- 10.8M
Traceback (most recent call last):
  File "/tmp/langtek_venv/lib/python3.13/site-packages/urllib3/connection.py", line 222, in _new_conn
    sock = self._resolver.create_connection(
        (self._dns_host, self.port or self.default_port),
    ...<8 lines>...
        default_socket_family=self._socket_family,
    )
  File "/tmp/langtek_venv/lib/python3.13/site-packages/urllib3/contrib/resolver/protocols.py", line 299, in create_connection
    raise err
  File "/tmp/langtek_venv/lib/python3.13/site-packages/urllib3/contrib/resolver/protocols.py", line 269, in create_connection
    sock.connect(sa)
    ~~~~~~~~~~~~^^^^
OSError: [Errno 101] Network is unreachable

The above exception was the direct cause of the following exception:

Traceback (most recent call last):
  File "/tmp/langtek_venv/lib/python3.13/site-packages/urllib3/connectionpool.py", line 1713, in urlopen
    response = self._make_request(  # type: ignore[call-overload,misc]
        conn,
    ...<15 lines>...
        extension=extension,
    )
  File "/tmp/langtek_venv/lib/python3.13/site-packages/urllib3/connectionpool.py", line 1257, in _make_request
    raise new_e
  File "/tmp/langtek_venv/lib/python3.13/site-packages/urllib3/connectionpool.py", line 1233, in _make_request
    self._validate_conn(conn)
    ~~~~~~~~~~~~~~~~~~~^^^^^^
  File "/tmp/langtek_venv/lib/python3.13/site-packages/urllib3/connectionpool.py", line 2292, in _validate_conn
    super()._validate_conn(conn)
    ~~~~~~~~~~~~~~~~~~~~~~^^^^^^
  File "/tmp/langtek_venv/lib/python3.13/site-packages/urllib3/connectionpool.py", line 788, in _validate_conn
    conn.connect()
    ~~~~~~~~~~~~^^
  File "/tmp/langtek_venv/lib/python3.13/site-packages/urllib3/connection.py", line 761, in connect
    self.sock = sock = self._new_conn()
                       ~~~~~~~~~~~~~~^^
  File "/tmp/langtek_venv/lib/python3.13/site-packages/urllib3/connection.py", line 242, in _new_conn
    raise NewConnectionError(
        self, f"Failed to establish a new connection: {e}"
    ) from e
urllib3.exceptions.NewConnectionError: <urllib3.connection.HTTPSConnection object at 0x7e8ff5729d30>: Failed to establish a new connection: [Errno 101] Network is unreachable

The above exception was the direct cause of the following exception:

Traceback (most recent call last):
  File "/tmp/langtek_venv/lib/python3.13/site-packages/requests/adapters.py", line 667, in send
    resp = conn.urlopen(
        method=request.method,
    ...<9 lines>...
        chunked=chunked,
    )
  File "/tmp/langtek_venv/lib/python3.13/site-packages/urllib3/connectionpool.py", line 1791, in urlopen
    retries = retries.increment(
        method, url, error=new_e, _pool=self, _stacktrace=sys.exc_info()[2]
    )
  File "/tmp/langtek_venv/lib/python3.13/site-packages/urllib3/util/retry.py", line 544, in increment
    raise MaxRetryError(_pool, url, reason) from reason  # type: ignore[arg-type]
    ^^^^^^^^^^^^^^^^^^^^^^^^^^^^^^^^^^^^^^^^^^^^^^^^^^^
urllib3.exceptions.MaxRetryError: HTTPSConnectionPool(host='geolocation.onetrust.com', port=443): Max retries exceeded with url: /cookieconsentpub/v1/geo/location (Caused by NewConnectionError('<urllib3.connection.HTTPSConnection object at 0x7e8ff5729d30>: Failed to establish a new connection: [Errno 101] Network is unreachable'))

During handling of the above exception, another exception occurred:

Traceback (most recent call last):
  File "/tmp/langtek_venv/lib/python3.13/site-packages/translators/server.py", line 354, in get_region_of_server
    data = json.loads(requests.get(self.get_addr_url, headers=_headers_fn(self.get_addr_url)).text[9:-2])
                      ~~~~~~~~~~~~^^^^^^^^^^^^^^^^^^^^^^^^^^^^^^^^^^^^^^^^^^^^^^^^^^^^^^^^^^^
  File "/tmp/langtek_venv/lib/python3.13/site-packages/requests/api.py", line 73, in get
    return request("get", url, params=params, **kwargs)
  File "/tmp/langtek_venv/lib/python3.13/site-packages/requests/api.py", line 59, in request
    return session.request(method=method, url=url, **kwargs)
           ~~~~~~~~~~~~~~~^^^^^^^^^^^^^^^^^^^^^^^^^^^^^^^^^^
  File "/tmp/langtek_venv/lib/python3.13/site-packages/requests/sessions.py", line 589, in request
    resp = self.send(prep, **send_kwargs)
  File "/tmp/langtek_venv/lib/python3.13/site-packages/requests/sessions.py", line 703, in send
    r = adapter.send(request, **kwargs)
  File "/tmp/langtek_venv/lib/python3.13/site-packages/requests/adapters.py", line 700, in send
    raise ConnectionError(e, request=request)
requests.exceptions.ConnectionError: HTTPSConnectionPool(host='geolocation.onetrust.com', port=443): Max retries exceeded with url: /cookieconsentpub/v1/geo/location (Caused by NewConnectionError('<urllib3.connection.HTTPSConnection object at 0x7e8ff5729d30>: Failed to establish a new connection: [Errno 101] Network is unreachable'))

During handling of the above exception, another exception occurred:

Traceback (most recent call last):
  File "/tmp/langtek_venv/lib/python3.13/site-packages/urllib3/connection.py", line 222, in _new_conn
    sock = self._resolver.create_connection(
        (self._dns_host, self.port or self.default_port),
    ...<8 lines>...
        default_socket_family=self._socket_family,
    )
  File "/tmp/langtek_venv/lib/python3.13/site-packages/urllib3/contrib/resolver/protocols.py", line 299, in create_connection
    raise err
  File "/tmp/langtek_venv/lib/python3.13/site-packages/urllib3/contrib/resolver/protocols.py", line 269, in create_connection
    sock.connect(sa)
    ~~~~~~~~~~~~^^^^
ConnectionRefusedError: [Errno 111] Connection refused

The above exception was the direct cause of the following exception:

Traceback (most recent call last):
  File "/tmp/langtek_venv/lib/python3.13/site-packages/urllib3/connectionpool.py", line 1713, in urlopen
    response = self._make_request(  # type: ignore[call-overload,misc]
        conn,
    ...<15 lines>...
        extension=extension,
    )
  File "/tmp/langtek_venv/lib/python3.13/site-packages/urllib3/connectionpool.py", line 1257, in _make_request
    raise new_e
  File "/tmp/langtek_venv/lib/python3.13/site-packages/urllib3/connectionpool.py", line 1233, in _make_request
    self._validate_conn(conn)
    ~~~~~~~~~~~~~~~~~~~^^^^^^
  File "/tmp/langtek_venv/lib/python3.13/site-packages/urllib3/connectionpool.py", line 2292, in _validate_conn
    super()._validate_conn(conn)
    ~~~~~~~~~~~~~~~~~~~~~~^^^^^^
  File "/tmp/langtek_venv/lib/python3.13/site-packages/urllib3/connectionpool.py", line 788, in _validate_conn
    conn.connect()
    ~~~~~~~~~~~~^^
  File "/tmp/langtek_venv/lib/python3.13/site-packages/urllib3/connection.py", line 761, in connect
    self.sock = sock = self._new_conn()
                       ~~~~~~~~~~~~~~^^
  File "/tmp/langtek_venv/lib/python3.13/site-packages/urllib3/connection.py", line 242, in _new_conn
    raise NewConnectionError(
        self, f"Failed to establish a new connection: {e}"
    ) from e
urllib3.exceptions.NewConnectionError: <urllib3.connection.HTTPSConnection object at 0x7e8ff4334190>: Failed to establish a new connection: [Errno 111] Connection refused

The above exception was the direct cause of the following exception:

Traceback (most recent call last):
  File "/tmp/langtek_venv/lib/python3.13/site-packages/requests/adapters.py", line 667, in send
    resp = conn.urlopen(
        method=request.method,
    ...<9 lines>...
        chunked=chunked,
    )
  File "/tmp/langtek_venv/lib/python3.13/site-packages/urllib3/connectionpool.py", line 1791, in urlopen
    retries = retries.increment(
        method, url, error=new_e, _pool=self, _stacktrace=sys.exc_info()[2]
    )
  File "/tmp/langtek_venv/lib/python3.13/site-packages/urllib3/util/retry.py", line 544, in increment
    raise MaxRetryError(_pool, url, reason) from reason  # type: ignore[arg-type]
    ^^^^^^^^^^^^^^^^^^^^^^^^^^^^^^^^^^^^^^^^^^^^^^^^^^^
urllib3.exceptions.MaxRetryError: HTTPSConnectionPool(host='ip.taobao.com', port=443): Max retries exceeded with url: /outGetIpInfo (Caused by NewConnectionError('<urllib3.connection.HTTPSConnection object at 0x7e8ff4334190>: Failed to establish a new connection: [Errno 111] Connection refused'))

During handling of the above exception, another exception occurred:

Traceback (most recent call last):
  File "/tmp/langtek_venv/lib/python3.13/site-packages/translators/server.py", line 361, in get_region_of_server
    data = requests.post(url=self.ip_tb_add_url, data=payload, headers=_headers_fn(self.ip_tb_add_url)).json().get('data')
           ~~~~~~~~~~~~~^^^^^^^^^^^^^^^^^^^^^^^^^^^^^^^^^^^^^^^^^^^^^^^^^^^^^^^^^^^^^^^^^^^^^^^^^^^^^^^
  File "/tmp/langtek_venv/lib/python3.13/site-packages/requests/api.py", line 115, in post
    return request("post", url, data=data, json=json, **kwargs)
  File "/tmp/langtek_venv/lib/python3.13/site-packages/requests/api.py", line 59, in request
    return session.request(method=method, url=url, **kwargs)
           ~~~~~~~~~~~~~~~^^^^^^^^^^^^^^^^^^^^^^^^^^^^^^^^^^
  File "/tmp/langtek_venv/lib/python3.13/site-packages/requests/sessions.py", line 589, in request
    resp = self.send(prep, **send_kwargs)
  File "/tmp/langtek_venv/lib/python3.13/site-packages/requests/sessions.py", line 703, in send
    r = adapter.send(request, **kwargs)
  File "/tmp/langtek_venv/lib/python3.13/site-packages/requests/adapters.py", line 700, in send
    raise ConnectionError(e, request=request)
requests.exceptions.ConnectionError: HTTPSConnectionPool(host='ip.taobao.com', port=443): Max retries exceeded with url: /outGetIpInfo (Caused by NewConnectionError('<urllib3.connection.HTTPSConnection object at 0x7e8ff4334190>: Failed to establish a new connection: [Errno 111] Connection refused'))

During handling of the above exception, another exception occurred:

Traceback (most recent call last):
  File "/home/adminotaur/Documents/git/langtek/db/translate_builder.py", line 6, in <module>
    import translators as ts
  File "/tmp/langtek_venv/lib/python3.13/site-packages/translators/__init__.py", line 5, in <module>
    from translators.server import (
    ...<6 lines>...
    )
  File "/tmp/langtek_venv/lib/python3.13/site-packages/translators/server.py", line 5907, in <module>
    tss = TranslatorsServer()
  File "/tmp/langtek_venv/lib/python3.13/site-packages/translators/server.py", line 5633, in __init__
    self.server_region = self.get_region_of_server(if_print_region=False)
                         ~~~~~~~~~~~~~~~~~~~~~~~~~^^^^^^^^^^^^^^^^^^^^^^^
  File "/tmp/langtek_venv/lib/python3.13/site-packages/translators/server.py", line 365, in get_region_of_server
    raise TranslatorError('\n'.join([connect_info, try_info, str(e)]))
translators.server.TranslatorError: Unable to connect the Internet.
Try `os.environ["translators_default_region"] = "EN" or "CN"` before `import translators`
HTTPSConnectionPool(host='ip.taobao.com', port=443): Max retries exceeded with url: /outGetIpInfo (Caused by NewConnectionError('<urllib3.connection.HTTPSConnection object at 0x7e8ff4334190>: Failed to establish a new connection: [Errno 111] Connection refused'))
Cleaning up temporary files...
[adminotaur@hal9000 db]$ 